Workbook
Name Slicer_Customer: #N/A
Name Slicer_OrderDate: #N/A
Name Slicer_Region: #N/A
Name Slicer_Status: #N/A

Sheet Pivot
A2: Revenue by Region | D2: Monthly Revenue Analysis | G2: Collection By Region | J2: Outstanding by Customer | M2: Aging Analysis
A3: Region | B3: Sum of Revenue | D3: Row Labels | E3: Sum of OrderValue | G3: Row Labels | H3: Sum of AmountPaid | J3: Row Labels | K3: Sum of Outstanding Amount | M3: Row Labels | N3: Sum of Outstanding Amount
A4: East | B4: 4060000 | D4: Apr | E4: 2505000 | G4: East | H4: 2827250 | J4: Shinde Provision Mart | K4: 357000 | M4: 0-30 Days | N4: 598500
A5: North | B5: 4421000 | D5: Aug | E5: 3383000 | G5: North | H5: 2686250 | J5: Lokare Traders | K5: 330000 | M5: 31-60 Days | N5: 199750
A6: South | B6: 4866000 | D6: Dec | E6: 3233000 | G6: South | H6: 3194750 | J6: Rastogi General Store | K6: 281750 | M6: 90+ Days | N6: 10235000
A7: West | B7: 22018000 | D7: Feb | E7: 3268000 | G7: West | H7: 15623500 | J7: Ghosh Departmental | K7: 253000 | M7: Grand Total | N7: 11033250
A8: Grand Total | B8: 35365000 | D8: Jan | E8: 2221000 | G8: Grand Total | H8: 24331750 | J8: Chavan Supermart | K8: 243000
D9: Jul | E9: 2783000 | J9: Nimkar General Store | K9: 235000
D10: Jun | E10: 2044000 | J10: Hegde Provision Store | K10: 227500
D11: Mar | E11: 2753000 | J11: Londhe Retail | K11: 220000
D12: May | E12: 3545000 | J12: Yashwante General Store | K12: 212500
D13: Nov | E13: 2531000 | J13: Qureshi Traders | K13: 212500
D14: Oct | E14: 3735000 | J14: Verma Provision Mart | K14: 208000
D15: Sep | E15: 3364000 | J15: Magar Kirana Bhandar | K15: 206500
D16: Grand Total | E16: 35365000 | J16: Rao Enterprises | K16: 197000
J17: Nair General Stores | K17: 193000
J18: Zende Traders | K18: 188000
J19: Bose Brothers Retail | K19: 183000
J20: Naik Provision Bhandar | K20: 181250
J21: Wani General Store | K21: 177500
J22: Bansal Provision Store | K22: 173000
J23: Iyer Supermart | K23: 167000
J24: Deshpande Supermart | K24: 162500
J25: Walia Brothers | K25: 151250
J26: Lal Brothers | K26: 150000
J27: Salve Stores | K27: 150000
J28: Desai Provision Store | K28: 150000
... J106: Grand Total | K106: 11033250

Sheet O2C_Data
A1: OrderID | B1: Customer | C1: Region | D1: Month | E1: OrderDate | F1: InvoiceDate | G1: DueDate | H1: PaymentDate | I1: OrderValue | J1: AmountPaid | K1: Status | L1: Days to invoice | M1: CollectionDays | N1: Outstanding Amount | O1: Aging Bucket
A2: O0001 | B2: Yewale Kirana | C2: West | D2: =MID(E2, 4, 3) -> Feb | E2: 27-Feb-25 | F2: 28-Feb-25 | G2: 30-Mar-25 | H2: 09-Mar-25 | I2: 50000 | J2: 50000 | K2: Paid | L2: =F2-E2 -> 1 | M2: =IF(H2="",TODAY()-F2,H2-F2) -> 9 | N2: =I2-J2 -> 0 | O2: =IF(M2<=30,"0-30 Days", IF(M2<=60,"31-60 Days", IF(M2<=90,"61-90 Days","90+ Days"))) -> 0-30 Days
A3: O0002 | B3: Raskar General Store | C3: West | D3: =MID(E3, 4, 3) -> Feb | E3: 22-Feb-25 | F3: 25-Feb-25 | G3: 27-Mar-25 | H3: 15-Mar-25 | I3: 55000 | J3: 55000 | K3: Paid | L3: =F3-E3 -> 3 | M3: =IF(H3="",TODAY()-F3,H3-F3) -> 18 | N3: =I3-J3 -> 0 | O3: =IF(M3<=30,"0-30 Days", IF(M3<=60,"31-60 Days", IF(M3<=90,"61-90 Days","90+ Days"))) -> 0-30 Days
A4: O0003 | B4: Gupta Traders | C4: North | D4: =MID(E4, 4, 3) -> Jan | E4: 16-Jan-25 | F4: 17-Jan-25 | G4: 16-Feb-25 | H4: 10-Feb-25 | I4: 30000 | J4: 30000 | K4: Paid | L4: =F4-E4 -> 1 | M4: =IF(H4="",TODAY()-F4,H4-F4) -> 24 | N4: =I4-J4 -> 0 | O4: =IF(M4<=30,"0-30 Days", IF(M4<=60,"31-60 Days", IF(M4<=90,"61-90 Days","90+ Days"))) -> 0-30 Days
A5: O0004 | B5: Iyer Supermart | C5: South | D5: =MID(E5, 4, 3) -> Oct | E5: 15-Oct-25 | F5: 16-Oct-25 | G5: 15-Nov-25 | H5: 04-Nov-25 | I5: 55000 | J5: 55000 | K5: Paid | L5: =F5-E5 -> 1 | M5: =IF(H5="",TODAY()-F5,H5-F5) -> 19 | N5: =I5-J5 -> 0 | O5: =IF(M5<=30,"0-30 Days", IF(M5<=60,"31-60 Days", IF(M5<=90,"61-90 Days","90+ Days"))) -> 0-30 Days
A6: O0005 | B6: Raut Supermart | C6: East | D6: =MID(E6, 4, 3) -> May | E6: 23-May-25 | F6: 24-May-25 | G6: 23-Jun-25 | H6: 04-Jul-25 | I6: 25000 | J6: 25000 | K6: Paid Late | L6: =F6-E6 -> 1 | M6: =IF(H6="",TODAY()-F6,H6-F6) -> 41 | N6: =I6-J6 -> 0 | O6: =IF(M6<=30,"0-30 Days", IF(M6<=60,"31-60 Days", IF(M6<=90,"61-90 Days","90+ Days"))) -> 31-60 Days
A7: O0006 | B7: Yadav General Store | C7: East | D7: =MID(E7, 4, 3) -> Mar | E7: 21-Mar-25 | F7: 22-Mar-25 | G7: 21-Apr-25 | H7: 08-Apr-25 | I7: 75000 | J7: 75000 | K7: Paid | L7: =F7-E7 -> 1 | M7: =IF(H7="",TODAY()-F7,H7-F7) -> 17 | N7: =I7-J7 -> 0 | O7: =IF(M7<=30,"0-30 Days", IF(M7<=60,"31-60 Days", IF(M7<=90,"61-90 Days","90+ Days"))) -> 0-30 Days
A8: O0007 | B8: Agarwal Super Store | C8: East | D8: =MID(E8, 4, 3) -> Jul | E8: 03-Jul-25 | F8: 05-Jul-25 | G8: 04-Aug-25 | I8: 50000 | J8: 0 | K8: Overdue | L8: =F8-E8 -> 2 | M8: =IF(H8="",TODAY()-F8,H8-F8) -> 346 | N8: =I8-J8 -> 50000 | O8: =IF(M8<=30,"0-30 Days", IF(M8<=60,"31-60 Days", IF(M8<=90,"61-90 Days","90+ Days"))) -> 90+ Days
A9: O0008 | B9: Pansare Stores | C9: West | D9: =MID(E9, 4, 3) -> Aug | E9: 24-Aug-25 | F9: 27-Aug-25 | G9: 26-Sep-25 | I9: 15000 | J9: 0 | K9: Cancelled | L9: =F9-E9 -> 3 | M9: =IF(H9="",TODAY()-F9,H9-F9) -> 293 | N9: =I9-J9 -> 15000 | O9: =IF(M9<=30,"0-30 Days", IF(M9<=60,"31-60 Days", IF(M9<=90,"61-90 Days","90+ Days"))) -> 90+ Days
A10: O0009 | B10: Londhe Retail | C10: West | D10: =MID(E10, 4, 3) -> Feb | E10: 10-Feb-25 | F10: 13-Feb-25 | G10: 15-Mar-25 | I10: 60000 | J10: 0 | K10: Overdue | L10: =F10-E10 -> 3 | M10: =IF(H10="",TODAY()-F10,H10-F10) -> 488 | N10: =I10-J10 -> 60000 | O10: =IF(M10<=30,"0-30 Days", IF(M10<=60,"31-60 Days", IF(M10<=90,"61-90 Days","90+ Days"))) -> 90+ Days
A11: O0010 | B11: Vitkar Stores | C11: South | D11: =MID(E11, 4, 3) -> Jul | E11: 05-Jul-25 | F11: 08-Jul-25 | G11: 07-Aug-25 | I11: 30000 | J11: 0 | K11: Outstanding | L11: =F11-E11 -> 3 | M11: =IF(H11="",TODAY()-F11,H11-F11) -> 343 | N11: =I11-J11 -> 30000 | O11: =IF(M11<=30,"0-30 Days", IF(M11<=60,"31-60 Days", IF(M11<=90,"61-90 Days","90+ Days"))) -> 90+ Days
A12: O0011 | B12: Singh Departmental Store | C12: North | D12: =MID(E12, 4, 3) -> Dec | E12: 05-Dec-25 | F12: 06-Dec-25 | G12: 05-Jan-26 | I12: 60000 | J12: 0 | K12: Cancelled | L12: =F12-E12 -> 1 | M12: =IF(H12="",TODAY()-F12,H12-F12) -> 192 | N12: =I12-J12 -> 60000 | O12: =IF(M12<=30,"0-30 Days", IF(M12<=60,"31-60 Days", IF(M12<=90,"61-90 Days","90+ Days"))) -> 90+ Days
A13: O0012 | B13: Shetty Supermart | C13: South | D13: =MID(E13, 4, 3) -> Feb | E13: 21-Feb-25 | F13: 23-Feb-25 | G13: 25-Mar-25 | H13: 11-Mar-25 | I13: 50000 | J13: 50000 | K13: Paid | L13: =F13-E13 -> 2 | M13: =IF(H13="",TODAY()-F13,H13-F13) -> 16 | N13: =I13-J13 -> 0 | O13: =IF(M13<=30,"0-30 Days", IF(M13<=60,"31-60 Days", IF(M13<=90,"61-90 Days","90+ Days"))) -> 0-30 Days
A14: O0013 | B14: Jain Retail Mart | C14: West | D14: =MID(E14, 4, 3) -> Jul | E14: 09-Jul-25 | F14: 11-Jul-25 | G14: 10-Aug-25 | H14: 02-Sep-25 | I14: 30000 | J14: 30000 | K14: Paid Late | L14: =F14-E14 -> 2 | M14: =IF(H14="",TODAY()-F14,H14-F14) -> 53 | N14: =I14-J14 -> 0 | O14: =IF(M14<=30,"0-30 Days", IF(M14<=60,"31-60 Days", IF(M14<=90,"61-90 Days","90+ Days"))) -> 31-60 Days
A15: O0014 | B15: Gawali Retail | C15: West | D15: =MID(E15, 4, 3) -> Nov | E15: 28-Nov-25 | F15: 29-Nov-25 | G15: 29-Dec-25 | H15: 11-Dec-25 | I15: 25000 | J15: 25000 | K15: Paid | L15: =F15-E15 -> 1 | M15: =IF(H15="",TODAY()-F15,H15-F15) -> 12 | N15: =I15-J15 -> 0 | O15: =IF(M15<=30,"0-30 Days", IF(M15<=60,"31-60 Days", IF(M15<=90,"61-90 Days","90+ Days"))) -> 0-30 Days
A16: O0015 | B16: Jain Retail Mart | C16: West | D16: =MID(E16, 4, 3) -> Aug | E16: 25-Aug-25 | F16: 27-Aug-25 | G16: 26-Sep-25 | I16: 50000 | J16: 0 | K16: Cancelled | L16: =F16-E16 -> 2 | M16: =IF(H16="",TODAY()-F16,H16-F16) -> 293 | N16: =I16-J16 -> 50000 | O16: =IF(M16<=30,"0-30 Days", IF(M16<=60,"31-60 Days", IF(M16<=90,"61-90 Days","90+ Days"))) -> 90+ Days
A17: O0016 | B17: Yewale Kirana | C17: West | D17: =MID(E17, 4, 3) -> Dec | E17: 19-Dec-25 | F17: 22-Dec-25 | G17: 21-Jan-26 | H17: 17-Feb-26 | I17: 40000 | J17: 40000 | K17: Paid Late | L17: =F17-E17 -> 3 | M17: =IF(H17="",TODAY()-F17,H17-F17) -> 57 | N17: =I17-J17 -> 0 | O17: =IF(M17<=30,"0-30 Days", IF(M17<=60,"31-60 Days", IF(M17<=90,"61-90 Days","90+ Days"))) -> 31-60 Days
A18: O0017 | B18: Varale Stores | C18: West | D18: =MID(E18, 4, 3) -> Jan | E18: 29-Jan-25 | F18: 30-Jan-25 | G18: 01-Mar-25 | I18: 8000 | J18: 0 | K18: Overdue | L18: =F18-E18 -> 1 | M18: =IF(H18="",TODAY()-F18,H18-F18) -> 502 | N18: =I18-J18 -> 8000 | O18: =IF(M18<=30,"0-30 Days", IF(M18<=60,"31-60 Days", IF(M18<=90,"61-90 Days","90+ Days"))) -> 90+ Days
A19: O0018 | B19: Oswal Supermart | C19: West | D19: =MID(E19, 4, 3) -> May | E19: 18-May-25 | F19: 19-May-25 | G19: 18-Jun-25 | H19: 13-Jun-25 | I19: 30000 | J19: 7500 | K19: Partial | L19: =F19-E19 -> 1 | M19: =IF(H19="",TODAY()-F19,H19-F19) -> 25 | N19: =I19-J19 -> 22500 | O19: =IF(M19<=30,"0-30 Days", IF(M19<=60,"31-60 Days", IF(M19<=90,"61-90 Days","90+ Days"))) -> 0-30 Days
A20: O0019 | B20: Aher Provision Mart | C20: West | D20: =MID(E20, 4, 3) -> Sep | E20: 13-Sep-25 | F20: 15-Sep-25 | G20: 15-Oct-25 | H20: 24-Sep-25 | I20: 22000 | J20: 22000 | K20: Paid | L20: =F20-E20 -> 2 | M20: =IF(H20="",TODAY()-F20,H20-F20) -> 9 | N20: =I20-J20 -> 0 | O20: =IF(M20<=30,"0-30 Days", IF(M20<=60,"31-60 Days", IF(M20<=90,"61-90 Days","90+ Days"))) -> 0-30 Days
A21: O0020 | B21: Upadhyay Stores | C21: East | D21: =MID(E21, 4, 3) -> Oct | E21: 15-Oct-25 | F21: 18-Oct-25 | G21: 17-Nov-25 | I21: 50000 | J21: 0 | K21: Outstanding | L21: =F21-E21 -> 3 | M21: =IF(H21="",TODAY()-F21,H21-F21) -> 241 | N21: =I21-J21 -> 50000 | O21: =IF(M21<=30,"0-30 Days", IF(M21<=60,"31-60 Days", IF(M21<=90,"61-90 Days","90+ Days"))) -> 90+ Days
A22: O0021 | B22: Salve Stores | C22: West | D22: =MID(E22, 4, 3) -> Oct | E22: 26-Oct-25 | F22: 28-Oct-25 | G22: 27-Nov-25 | H22: 06-Nov-25 | I22: 100000 | J22: 100000 | K22: Paid | L22: =F22-E22 -> 2 | M22: =IF(H22="",TODAY()-F22,H22-F22) -> 9 | N22: =I22-J22 -> 0 | O22: =IF(M22<=30,"0-30 Days", IF(M22<=60,"31-60 Days", IF(M22<=90,"61-90 Days","90+ Days"))) -> 0-30 Days
A23: O0022 | B23: Ekbote Supermart | C23: West | D23: =MID(E23, 4, 3) -> Sep | E23: 10-Sep-25 | F23: 11-Sep-25 | G23: 11-Oct-25 | I23: 8000 | J23: 0 | K23: Overdue | L23: =F23-E23 -> 1 | M23: =IF(H23="",TODAY()-F23,H23-F23) -> 278 | N23: =I23-J23 -> 8000 | O23: =IF(M23<=30,"0-30 Days", IF(M23<=60,"31-60 Days", IF(M23<=90,"61-90 Days","90+ Days"))) -> 90+ Days
A24: O0023 | B24: Iyengar Supermart | C24: South | D24: =MID(E24, 4, 3) -> Nov | E24: 18-Nov-25 | F24: 19-Nov-25 | G24: 19-Dec-25 | H24: 01-Jan-26 | I24: 18000 | J24: 18000 | K24: Paid Late | L24: =F24-E24 -> 1 | M24: =IF(H24="",TODAY()-F24,H24-F24) -> 43 | N24: =I24-J24 -> 0 | O24: =IF(M24<=30,"0-30 Days", IF(M24<=60,"31-60 Days", IF(M24<=90,"61-90 Days","90+ Days"))) -> 31-60 Days
A25: O0024 | B25: Londhe Retail | C25: West | D25: =MID(E25, 4, 3) -> Nov | E25: 02-Nov-25 | F25: 04-Nov-25 | G25: 04-Dec-25 | H25: 26-Nov-25 | I25: 45000 | J25: 45000 | K25: Paid | L25: =F25-E25 -> 2 | M25: =IF(H25="",TODAY()-F25,H25-F25) -> 22 | N25: =I25-J25 -> 0 | O25: =IF(M25<=30,"0-30 Days", IF(M25<=60,"31-60 Days", IF(M25<=90,"61-90 Days","90+ Days"))) -> 0-30 Days
A26: O0025 | B26: Patel Kirana | C26: West | D26: =MID(E26, 4, 3) -> Dec | E26: 15-Dec-25 | F26: 18-Dec-25 | G26: 17-Jan-26 | H26: 04-Feb-26 | I26: 15000 | J26: 15000 | K26: Paid Late | L26: =F26-E26 -> 3 | M26: =IF(H26="",TODAY()-F26,H26-F26) -> 48 | N26: =I26-J26 -> 0 | O26: =IF(M26<=30,"0-30 Days", IF(M26<=60,"31-60 Days", IF(M26<=90,"61-90 Days","90+ Days"))) -> 31-60 Days
A27: O0026 | B27: Suryawanshi Kirana | C27: South | D27: =MID(E27, 4, 3) -> May | E27: 17-May-25 | F27: 20-May-25 | G27: 19-Jun-25 | H27: 07-Jun-25 | I27: 75000 | J27: 75000 | K27: Paid | L27: =F27-E27 -> 3 | M27: =IF(H27="",TODAY()-F27,H27-F27) -> 18 | N27: =I27-J27 -> 0 | O27: =IF(M27<=30,"0-30 Days", IF(M27<=60,"31-60 Days", IF(M27<=90,"61-90 Days","90+ Days"))) -> 0-30 Days
A28: O0027 | B28: Jain Retail Mart | C28: West | D28: =MID(E28, 4, 3) -> Aug | E28: 21-Aug-25 | F28: 22-Aug-25 | G28: 21-Sep-25 | I28: 50000 | J28: 0 | K28: Cancelled | L28: =F28-E28 -> 1 | M28: =IF(H28="",TODAY()-F28,H28-F28) -> 298 | N28: =I28-J28 -> 50000 | O28: =IF(M28<=30,"0-30 Days", IF(M28<=60,"31-60 Days", IF(M28<=90,"61-90 Days","90+ Days"))) -> 90+ Days
A29: O0028 | B29: Ubale Supermart | C29: East | D29: =MID(E29, 4, 3) -> Apr | E29: 02-Apr-25 | F29: 05-Apr-25 | G29: 05-May-25 | I29: 15000 | J29: 0 | K29: Overdue | L29: =F29-E29 -> 3 | M29: =IF(H29="",TODAY()-F29,H29-F29) -> 437 | N29: =I29-J29 -> 15000 | O29: =IF(M29<=30,"0-30 Days", IF(M29<=60,"31-60 Days", IF(M29<=90,"61-90 Days","90+ Days"))) -> 90+ Days
A30: O0029 | B30: Bansal Provision Store | C30: North | D30: =MID(E30, 4, 3) -> Nov | E30: 24-Nov-25 | F30: 27-Nov-25 | G30: 27-Dec-25 | H30: 07-Dec-25 | I30: 30000 | J30: 30000 | K30: Paid | L30: =F30-E30 -> 3 | M30: =IF(H30="",TODAY()-F30,H30-F30) -> 10 | N30: =I30-J30 -> 0 | O30: =IF(M30<=30,"0-30 Days", IF(M30<=60,"31-60 Days", IF(M30<=90,"61-90 Days","90+ Days"))) -> 0-30 Days
A31: O0030 | B31: Jagtap Kirana | C31: West | D31: =MID(E31, 4, 3) -> Sep | E31: 29-Sep-25 | F31: 30-Sep-25 | G31: 30-Oct-25 | H31: 08-Oct-25 | I31: 75000 | J31: 75000 | K31: Paid | L31: =F31-E31 -> 1 | M31: =IF(H31="",TODAY()-F31,H31-F31) -> 8 | N31: =I31-J31 -> 0 | O31: =IF(M31<=30,"0-30 Days", IF(M31<=60,"31-60 Days", IF(M31<=90,"61-90 Days","90+ Days"))) -> 0-30 Days
A32: O0031 | B32: Jadhav Kirana Mart | C32: West | D32: =MID(E32, 4, 3) -> Jun | E32: 07-Jun-25 | F32: 08-Jun-25 | G32: 08-Jul-25 | H32: 01-Jul-25 | I32: 8000 | J32: 8000 | K32: Paid | L32: =F32-E32 -> 1 | M32: =IF(H32="",TODAY()-F32,H32-F32) -> 23 | N32: =I32-J32 -> 0 | O32: =IF(M32<=30,"0-30 Days", IF(M32<=60,"31-60 Days", IF(M32<=90,"61-90 Days","90+ Days"))) -> 0-30 Days
A33: O0032 | B33: Nair General Stores | C33: South | D33: =MID(E33, 4, 3) -> Feb | E33: 13-Feb-25 | F33: 16-Feb-25 | G33: 18-Mar-25 | I33: 35000 | J33: 0 | K33: Overdue | L33: =F33-E33 -> 3 | M33: =IF(H33="",TODAY()-F33,H33-F33) -> 485 | N33: =I33-J33 -> 35000 | O33: =IF(M33<=30,"0-30 Days", IF(M33<=60,"31-60 Days", IF(M33<=90,"61-90 Days","90+ Days"))) -> 90+ Days
A34: O0033 | B34: Ubale Supermart | C34: East | D34: =MID(E34, 4, 3) -> Sep | E34: 30-Sep-25 | F34: 01-Oct-25 | G34: 31-Oct-25 | H34: 18-Nov-25 | I34: 20000 | J34: 20000 | K34: Paid Late | L34: =F34-E34 -> 1 | M34: =IF(H34="",TODAY()-F34,H34-F34) -> 48 | N34: =I34-J34 -> 0 | O34: =IF(M34<=30,"0-30 Days", IF(M34<=60,"31-60 Days", IF(M34<=90,"61-90 Days","90+ Days"))) -> 31-60 Days
A35: O0034 | B35: Kaur General Store | C35: North | D35: =MID(E35, 4, 3) -> May | E35: 16-May-25 | F35: 19-May-25 | G35: 18-Jun-25 | I35: 18000 | J35: 0 | K35: Cancelled | L35: =F35-E35 -> 3 | M35: =IF(H35="",TODAY()-F35,H35-F35) -> 393 | N35: =I35-J35 -> 18000 | O35: =IF(M35<=30,"0-30 Days", IF(M35<=60,"31-60 Days", IF(M35<=90,"61-90 Days","90+ Days"))) -> 90+ Days
A36: O0035 | B36: Jagtap Kirana | C36: West | D36: =MID(E36, 4, 3) -> Dec | E36: 20-Dec-25 | F36: 21-Dec-25 | G36: 20-Jan-26 | H36: 16-Jan-26 | I36: 60000 | J36: 60000 | K36: Paid | L36: =F36-E36 -> 1 | M36: =IF(H36="",TODAY()-F36,H36-F36) -> 26 | N36: =I36-J36 -> 0 | O36: =IF(M36<=30,"0-30 Days", IF(M36<=60,"31-60 Days", IF(M36<=90,"61-90 Days","90+ Days"))) -> 0-30 Days
A37: O0036 | B37: Aher Provision Mart | C37: West | D37: =MID(E37, 4, 3) -> Jul | E37: 11-Jul-25 | F37: 13-Jul-25 | G37: 12-Aug-25 | H37: 25-Jul-25 | I37: 45000 | J37: 45000 | K37: Paid | L37: =F37-E37 -> 2 | M37: =IF(H37="",TODAY()-F37,H37-F37) -> 12 | N37: =I37-J37 -> 0 | O37: =IF(M37<=30,"0-30 Days", IF(M37<=60,"31-60 Days", IF(M37<=90,"61-90 Days","90+ Days"))) -> 0-30 Days
A38: O0037 | B38: Rastogi General Store | C38: North | D38: =MID(E38, 4, 3) -> Feb | E38: 02-Feb-25 | F38: 04-Feb-25 | G38: 06-Mar-25 | H38: 14-Mar-25 | I38: 5000 | J38: 5000 | K38: Paid Late | L38: =F38-E38 -> 2 | M38: =IF(H38="",TODAY()-F38,H38-F38) -> 38 | N38: =I38-J38 -> 0 | O38: =IF(M38<=30,"0-30 Days", IF(M38<=60,"31-60 Days", IF(M38<=90,"61-90 Days","90+ Days"))) -> 31-60 Days
A39: O0038 | B39: Raut Supermart | C39: East | D39: =MID(E39, 4, 3) -> Apr | E39: 23-Apr-25 | F39: 24-Apr-25 | G39: 24-May-25 | I39: 10000 | J39: 0 | K39: Outstanding | L39: =F39-E39 -> 1 | M39: =IF(H39="",TODAY()-F39,H39-F39) -> 418 | N39: =I39-J39 -> 10000 | O39: =IF(M39<=30,"0-30 Days", IF(M39<=60,"31-60 Days", IF(M39<=90,"61-90 Days","90+ Days"))) -> 90+ Days
A40: O0039 | B40: Mehta Retail | C40: West | D40: =MID(E40, 4, 3) -> Apr | E40: 28-Apr-25 | F40: 29-Apr-25 | G40: 29-May-25 | I40: 8000 | J40: 0 | K40: Overdue | L40: =F40-E40 -> 1 | M40: =IF(H40="",TODAY()-F40,H40-F40) -> 413 | N40: =I40-J40 -> 8000 | O40: =IF(M40<=30,"0-30 Days", IF(M40<=60,"31-60 Days", IF(M40<=90,"61-90 Days","90+ Days"))) -> 90+ Days
...

Sheet Dashboard
B1: Total Revenue | G1: Total Collections | L1: OutstandingAmount | Q1: Collection Efficiency | V1: DSO

Sheet KPI
B3: Total Revenue | C3: Total Collections | D3: Outstanding Amount | E3: Collection Efficiency % | F3: Fulfillment Rate % | G3: Average Collection Days | H3: Daily Sales Outstanding(DSO)
B4: =SUM(O2C_Data!I215:I1001) -> 27933000 | C4: =SUM(O2C_Data!J2:J1001) -> 24331750 | D4: =SUM(O2C_Data!N2:N1001) -> 11033250 | E4: =C4/B4 -> 0.87107543 | F4: =COUNTIF(O2C_Data!K2:K1001,"Paid")/COUNTA(O2C_Data!2:1001) -> 0.035241393 | G4: =AVERAGE(O2C_Data!M2:M1001) -> 109.957 | H4: =(D4/B4)*365 -> 144.17128
